<?xml version="1.0" ?>
<robot xmlns:xacro="http://www.ros.org/wiki/xacro" name="rosbot">

  <!-- ====== Xacro ====== -->

  <xacro:macro name="inertial_box" params="mass x y z *origin">
    <inertial>
      <xacro:insert_block name="origin"/>
      <mass value="${mass}" />
      <inertia ixx="${(1/12) * mass * (y*y+z*z)}" ixy="0.0" ixz="0.0"
              iyy="${(1/12) * mass * (x*x+z*z)}" iyz="0.0"
              izz="${(1/12) * mass * (x*x+y*y)}" />
    </inertial>
  </xacro:macro>
  
  <xacro:macro name="inertial_cylinder" params="mass length radius *origin">
      <inertial>
          <xacro:insert_block name="origin"/>
          <mass value="${mass}" />
          <inertia ixx="${mass*(3*radius*radius + length*length)/12}" ixy="0.0" ixz="0.0"
                  iyy="${mass*(3*radius*radius + length*length)/12}" iyz="0.0"
                  izz="${mass*(radius*radius)/2}" />
      </inertial>
  </xacro:macro>

  <!-- ====== Colores ====== -->

  <material name="white">
    <color rgba="1 1 1 1"/>
  </material>
  <material name="orange">
    <color rgba="1 0.3 0.1 1"/>
  </material>
  <material name="blue">
    <color rgba="0.2 0.2 1 1"/>
  </material>
  
  <!-- ====== Colores Gazebo ====== -->

  <gazebo reference="chasis">
    <material>Gazebo/Blue</material>
  </gazebo>
  <gazebo reference="right_wheel">
    <material>Gazebo/White</material>
  </gazebo>
  <gazebo reference="left_wheel">
    <material>Gazebo/White</material>
  </gazebo>
  <gazebo reference="right_wheel_front">
    <material>Gazebo/White</material>
  </gazebo>
  <gazebo reference="left_wheel_front">
    <material>Gazebo/White</material>
  </gazebo>
    <gazebo reference="lidar_link">
    <material>Gazebo/Black</material>
  </gazebo>

  <!-- ===================================================================================== -->
  <!-- ========================== Descripcion del Robot ==================================== -->

  <link name="base_footprint"/>
  <joint name="base_joint" type="fixed">
    <parent link="base_footprint"/>
    <child link="chasis"/>
    <origin xyz="0 0 0.19"/>
  </joint>

  <!-- ====== Chasis ====== -->

  <link name="chasis">
    <visual>
      <geometry>
        <mesh filename="package://rosbot/meshes/box.STL" scale="0.001 0.001 0.001"/>
      </geometry>
      <origin xyz="-0.381 0.2 -0.075" rpy = "1.57 0 0"/>
      <material name="blue"/>
    </visual>
    <collision>
      <origin xyz="-0.381 0.2 -0.075" rpy = "1.57 0 0"/>
      <geometry>
        <mesh filename="package://rosbot/meshes/box.STL" scale="0.001 0.001 0.001"/>
      </geometry>
    </collision>
    <inertial>
      <origin xyz="-0.381 0.2 -0.075" rpy = "1.57 0 0"/>
      <mass value="30"/>
      <inertia  ixx="456250.0" ixy="0" ixz="0" iyy="1844000.0" iyz="0" izz="1500250.0" />
    </inertial>
  </link>

  <!-- ============ Traccion Trasera ============ -->
  <!-- ======= Right Rear Wheel ====== -->

  <link name="right_rear_wheel">
    <visual>
      <geometry>
        <cylinder length="0.08" radius="0.12"/>
      </geometry>
      <origin xyz="0 0 0"/>
      <material name="white"/>
    </visual>
    <collision>
      <origin xyz="0 0 0"/>
      <geometry>
        <cylinder length="0.08" radius="0.12"/>
      </geometry>
      <surface>
        <friction>
          <ode>
            <mu>1.0</mu> <!-- Fricción en la dirección primaria -->
            <mu2>1.0</mu2> <!-- Fricción en la dirección secundaria -->
          </ode>
        </friction>
        <contact>
          <ode>
            <kp>1000000.0</kp> <!-- Parámetros de contacto -->
            <kd>1.0</kd>
          </ode>
        </contact>
      </surface>
    </collision>
    <xacro:inertial_cylinder mass="1.0" length="0.08" radius="0.12">
      <origin xyz="0 0 0" rpy="0 0 0"/>
    </xacro:inertial_cylinder>
  </link>

  <joint name="joint_right_rear_wheel" type="continuous">
    <parent link="chasis"/>
    <child link="right_rear_wheel"/>
    <origin rpy="1.57 0 0" xyz="-0.27 -0.295 -0.07"/>
    <axis xyz="0 0 1"/>
  </joint>

  <!-- ====== Left Rear Wheel ====== -->

  <link name="left_rear_wheel">
    <visual>
      <geometry>
        <cylinder length="0.08" radius="0.12"/>
      </geometry>
      <origin xyz="0 0 0"/>
      <material name="white"/>
    </visual>
    <collision>
      <origin xyz="0 0 0"/>
      <geometry>
        <cylinder length="0.08" radius="0.12"/>
      </geometry>
      <surface>
        <friction>
          <ode>
            <mu>1.0</mu> <!-- Fricción en la dirección primaria -->
            <mu2>1.0</mu2> <!-- Fricción en la dirección secundaria -->
          </ode>
        </friction>
        <contact>
          <ode>
            <kp>1000000.0</kp> <!-- Parámetros de contacto -->
            <kd>1.0</kd>
          </ode>
        </contact>
      </surface>
    </collision>
    <xacro:inertial_cylinder mass="1.0" length="0.08" radius="0.12">
      <origin xyz="0 0 0" rpy="0 0 0"/>
    </xacro:inertial_cylinder>
  </link>

  <joint name="joint_left_rear_wheel" type="continuous">
    <parent link="chasis"/>
    <child link="left_rear_wheel"/>
    <origin rpy="1.57 0 0" xyz="-0.27 0.295 -0.07"/>
    <axis xyz="0 0 1"/>
  </joint>
 
  <!-- ============ Direccion Delantera ============ -->
  <!-- ====== Joint Master ====== -->

  <link name="master"/>
 
  <joint name="master_joint" type="revolute">
    <parent link="chasis"/>
    <child link="master"/>
    <origin xyz="0 0 0" rpy= "1.57 0 0"/>
    <axis xyz="0 1 0"/>
    <limit effort="100" velocity="1" lower="-0.78" upper="0.78"/>
  </joint>
  
  <!-- ====== Right Wheel Front Assembly ====== -->

  <link name="right_wheel_front_assembly">
    <visual>
      <geometry>
        <cylinder length="0.001" radius="0.04"/>
      </geometry>
      <origin xyz="0 0 0"/>
      <material name="white"/>
    </visual>
    <xacro:inertial_cylinder mass="0.01" length="0.00001" radius="0.04">
      <origin xyz="0 0 0" rpy="0 0 0"/>
    </xacro:inertial_cylinder>
  </link>

  <!-- ====== Right Wheel Front ====== -->

  <link name="right_wheel_front">
    <visual>
      <geometry>
        <cylinder length="0.08" radius="0.12"/>
      </geometry>
      <origin xyz="0 0 0"/>
      <material name="white"/>
    </visual>
    <collision>
      <origin xyz="0 0 0"/>
      <geometry>
        <cylinder length="0.08" radius="0.12"/>
      </geometry>
      <surface>
        <friction>
          <ode>
            <mu>1.0</mu> <!-- Fricción en la dirección primaria -->
            <mu2>1.0</mu2> <!-- Fricción en la dirección secundaria -->
          </ode>
        </friction>
        <contact>
          <ode>
            <kp>1000000.0</kp> <!-- Parámetros de contacto -->
            <kd>1.0</kd>
          </ode>
        </contact>
      </surface>
    </collision>
    <xacro:inertial_cylinder mass="1" length="0.08" radius="0.12">
      <origin xyz="0 0 0" rpy="0 0 0"/>
    </xacro:inertial_cylinder>
  </link>

  <joint name="joint_right_wheel_front" type="revolute">
    <parent link="chasis"/>
    <child link="right_wheel_front_assembly"/>
    <origin rpy="1.57 0 0" xyz="0.31 -0.295 -0.07"/>
    <axis xyz="0 1 0"/>
    <limit effort="100" lower="-0.78" upper="0.78" velocity="1"/>
    <mimic joint="master_joint" multiplier="1.0" offset="0"/>
  </joint>

  <joint name="joint_right_wheel_assembly" type="continuous">
    <parent link="right_wheel_front_assembly"/>
    <child link="right_wheel_front"/>
    <origin rpy="0 0 0" xyz="0 0 0"/>
    <axis xyz="0 0 1"/>
    <limit effort="100" velocity="1"/>
  </joint>

  <!-- ====== Left Wheel Front Assembly ====== -->

  <link name="left_wheel_front_assembly">
    <visual>
      <geometry>
        <cylinder length="0.001" radius="0.04"/>
      </geometry>
      <origin xyz="0 0 0"/>
      <material name="white"/>
    </visual>
    <xacro:inertial_cylinder mass="0.001" length="0.00001" radius="0.04">
      <origin xyz="0 0 0" rpy="0 0 0"/>
    </xacro:inertial_cylinder>
  </link>

  <!-- ====== Left Wheel Front ====== -->

  <link name="left_wheel_front">
    <visual>
      <geometry>
        <cylinder length="0.08" radius="0.12"/>
      </geometry>
      <origin xyz="0 0 0"/>
      <material name="white"/>
    </visual>
    <collision>
      <origin xyz="0 0 0"/>
      <geometry>
        <cylinder length="0.08" radius="0.12"/>
      </geometry>
      <surface>
        <friction>
          <ode>
            <mu>1.0</mu> <!-- Fricción en la dirección primaria -->
            <mu2>1.0</mu2> <!-- Fricción en la dirección secundaria -->
          </ode>
        </friction>
        <contact>
          <ode>
            <kp>1000000.0</kp> <!-- Parámetros de contacto -->
            <kd>1.0</kd>
          </ode>
        </contact>
      </surface>
    </collision>
    <xacro:inertial_cylinder mass="1" length="0.08" radius="0.12">
      <origin xyz="0 0 0" rpy="0 0 0"/>
    </xacro:inertial_cylinder>
  </link>

  <joint name="joint_left_wheel_assembly" type="continuous">
    <parent link="left_wheel_front_assembly"/>
    <child link="left_wheel_front"/>
    <origin rpy="0 0 0" xyz="0.0 0 0"/>
    <axis xyz="0 0 1"/>
    <limit effort="100" velocity="1"/>
  </joint>

  <joint name="joint_left_wheel_front" type="revolute">
    <parent link="chasis"/>
    <child link="left_wheel_front_assembly"/>
    <origin rpy="1.57 0 0" xyz="0.31 0.295 -0.07"/>
    <axis xyz="0 1 0"/>
    <limit effort="100" lower="-0.78" upper="0.78" velocity="1"/>
    <mimic joint="master_joint" multiplier="1.0" offset="0"/>
  </joint>
  
  <!-- ============ Percepcion ============ -->
  <!-- ====== Camara ====== -->

  <link name="camera_link">
    <visual>
      <origin xyz="0 0 0" rpy="0 -0.156 0"/>
      <geometry>
        <box size="0.04 0.17 0.03"/>
      </geometry>
    </visual>
    <collision>
      <origin xyz="0 0 0" rpy="0 -0.156 0"/>
      <geometry>
        <box size="0.04 0.17 0.03"/>
      </geometry>
    </collision>
    <xacro:inertial_box mass="0.181" x="0.04" y="0.17" z="0.03">
      <origin xyz="0 0 0" rpy="0 0 0"/>
    </xacro:inertial_box>
  </link>
  
  <joint name="camera_joint" type="fixed">
    <parent link="chasis"/>
    <child link="camera_link"/>
    <origin xyz=" 0.30 0 0.1" rpy="0 -0.156 0"/>
  </joint>

  <link name="camera_depth_frame"/>

  <joint name="camera_depth_joint" type="fixed">
    <origin xyz="0 0 0" rpy="0 0 0"/>
    <parent link="camera_link"/>
    <child link="camera_depth_frame"/>
  </joint>

  <gazebo reference="camera_link">
    <sensor name="depth_camera" type="depth">
      <visualize>true</visualize>
      <update_rate>30.0</update_rate>
      <camera name="camera">
        <horizontal_fov>1.047198</horizontal_fov>
        <image>
          <width>640</width>
          <height>480</height>
          <format>R8G8B8</format>
        </image>
        <clip>
          <near>0.05</near>
          <far>3</far>
        </clip>
      </camera>
      <plugin name="depth_camera_controller" filename="libgazebo_ros_camera.so">
        <baseline>0.2</baseline>
        <alwaysOn>true</alwaysOn>
        <updateRate>0.0</updateRate>
        <frameName>camera_depth_frame</frameName>
        <pointCloudCutoff>0.5</pointCloudCutoff>
        <pointCloudCutoffMax>3.0</pointCloudCutoffMax>
        <distortionK1>0</distortionK1>
        <distortionK2>0</distortionK2>
        <distortionK3>0</distortionK3>
        <distortionT1>0</distortionT1>
        <distortionT2>0</distortionT2>
        <CxPrime>0</CxPrime>
        <Cx>0</Cx>
        <Cy>0</Cy>
        <focalLength>0</focalLength>
        <hackBaseline>0</hackBaseline>
      </plugin>
    </sensor>
  </gazebo>

  <!-- ====== Lidar ====== -->

  <link name="lidar_link">
    <inertial>
      <origin xyz="0 0 0" rpy="0 0 0"/>
      <mass value="0.125"/>
      <inertia ixx="0.001"  ixy="0"  ixz="0" iyy="0.001" iyz="0" izz="0.001" />
    </inertial>
    <collision>
      <origin xyz="0 0 0" rpy="0 0 0"/>
      <geometry>
         <cylinder radius="0.05" length="0.05"/>
      </geometry>
    </collision>
    <visual>
      <origin xyz="0 0 0" rpy="0 0 0"/>
      <geometry>
         <cylinder radius="0.05" length="0.05"/>
      </geometry>
    </visual>
  </link>
     
  <joint name="lidar_joint" type="fixed">
    <parent link="chasis"/>
    <child link="lidar_link"/>
    <origin xyz=" 0.2 0 0.15" rpy="0 0 0"/>
  </joint>
     
  <gazebo reference="lidar_link">
    <sensor name="lidar" type="ray">
      <always_on>true</always_on>
      <visualize>true</visualize>
      <update_rate>5</update_rate>
      <ray>
        <scan>
          <horizontal>
            <samples>120</samples>
            <resolution>1.000000</resolution>
            <min_angle>-3.14159</min_angle>
            <max_angle>3.14159</max_angle>
          </horizontal>
        </scan>
        <range>
          <min>0.3</min>
          <max>15.0</max>
          <resolution>0.015</resolution>
        </range>
        <noise>
          <type>gaussian</type>
          <mean>0.0</mean>
          <stddev>0.01</stddev>
        </noise>
      </ray>
      <plugin name="scan" filename="libgazebo_ros_ray_sensor.so">
        <ros>
          <remapping>~/out:=scan</remapping>
        </ros>
        <output_type>sensor_msgs/LaserScan</output_type>
        <frame_name>lidar_link</frame_name>
      </plugin>
    </sensor>
  </gazebo>
    <!-- Ros2 Control-->
    
  <!-- Hardware interface for robot's controller -->
  <ros2_control  name="GazeboSystem"  type="system">
    <hardware>
      <plugin>gazebo_ros2_control/GazeboSystem</plugin>
    </hardware>

    <!-- Define the left wheel joint -->
    <joint name="joint_left_rear_wheel">
      <!-- Control the velocity of the left wheel -->
      <command_interface name="velocity">
        <param name="min">-10.0</param>
        <param name="max">10.0</param>
      </command_interface>
      <!-- Read the state of the left wheel's velocity -->
      <state_interface name="velocity"/>
      <state_interface name="position"/>
      <param name="initial_velocity">0.0</param>
    </joint>

    <!-- Define the right wheel joint -->
    <joint name="joint_right_rear_wheel">
      <!-- Control the velocity of the right wheel -->
      <command_interface name="velocity">
        <param name="min">-10.0</param>
        <param name="max">10.0</param>
      </command_interface>
      <!-- Read the state of the right wheel's velocity -->
      <state_interface name="velocity"/>
      <state_interface name="position"/>
      <param name="initial_velocity">0.0</param>
    </joint>

    <!-- Define the steering wheel joint (for direction control) -->
    <joint name="master_joint">
      <command_interface name="position">
        <param name="min">-1.5708</param> <!-- -90 degrees -->
        <param name="max">1.5708</param>  <!-- +90 degrees -->
      </command_interface>
      <state_interface name="position"/>
      <param name="initial_position">0.0</param>
    </joint>

    <!-- Define the steering wheel joint (for direction control) -->
    <joint name="joint_left_wheel_front">
      <param name="mimic">master_joint</param>
      <param name="multiplier">1</param>
      <command_interface name="position"/>
      <state_interface name="position"/>
    </joint>
        <!-- Define the steering wheel joint (for direction control) -->
    <joint name="joint_right_wheel_front">
      <param name="mimic">master_joint</param>
      <param name="multiplier">1</param>
      <command_interface name="position"/>
      <state_interface name="position"/>
    </joint>
  </ros2_control>

  <!-- Load robot's controller -->
  <gazebo>
    <plugin  filename="libgazebo_ros2_control.so"  name="gazebo_ros2_control">
      <robotNamespace>rosbot</robotNamespace>
      <parameters>/home/teo/rosbot/src/rosbot/config/controllers.yaml</parameters>
    </plugin>
  </gazebo>
</robot>
